File: m3_learning/papers/2023_RHEED_PLD_SrTiO3/XRD/treated_81nm-RSM_002.xrdml
<?xml version="1.0" encoding="utf-8"?>
<xrdMeasurements xmlns="http://www.xrdml.com/XRDMeasurement/2.2" xmlns:xsi="http://www.w3.org/2001/XMLSchema-instance" xsi:schemaLocation="http://www.xrdml.com/XRDMeasurement/2.2 http://www.xrdml.com/XRDMeasurement/2.2/XRDMeasurement.xsd" status="Completed">
	<comment>
		<entry>Configuration=3-axes Cradle_Reflection, Owner=User, Creation date=9/2/2021 3:55:24 PM</entry>
		<entry>Goniometer=Theta/Theta; Minimum step size 2Theta:0.0001; Minimum step size Omega:0.0001</entry>
		<entry>Sample stage=Chi-Phi-z stage 240 mm (reflection); Minimum step size Phi:0.01; Minimum step size Chi:0.01; Minimum step size Z:0.001</entry>
		<entry>Diffractometer system=EMPYREAN</entry>
		<entry>Measurement program=C:\PANalytical\Data Collector\Programs\Liyan Wu\Film programs\RSM slow 1.5 degree.xrdmp, Identifier={0A137119-D990-4D5D-A198-A9BB75A0EC1A}</entry>
	</comment>
	<sample type="To be analyzed">
		<id/>
		<name/>
		<preparedBy/>
	</sample>
	<xrdMeasurement status="Completed" measurementType="Area measurement" measurementStepAxis="Omega-2Theta" sampleMode="Reflection">
		<comment>
			<entry>PHD Lower Level = 4.02 (keV), PHD Upper Level = 11.26 (keV)</entry>
		</comment>
		<usedWavelength intended="K-Alpha">
			<kAlpha1 unit="Angstrom">1.5405980</kAlpha1>
			<kAlpha2 unit="Angstrom">1.5444260</kAlpha2>
			<kBeta unit="Angstrom">1.3922500</kBeta>
			<ratioKAlpha2KAlpha1>0</ratioKAlpha2KAlpha1>
		</usedWavelength>
		<incidentBeamPath>
			<radius unit="mm">240.00</radius>
			<xRayTube id="1010048" name="Empyrean Cu LFF HR (9430 033 7310x) DK432574">
				<tension unit="kV">45.0</tension>
				<current unit="mA">40.0</current>
				<anodeMaterial>Cu</anodeMaterial>
				<focus type="Line">
					<length unit="mm">12.0</length>
					<width unit="mm">0.4</width>
					<takeOffAngle unit="deg">4.4</takeOffAngle>
				</focus>
			</xRayTube>
			<xRayMirror xsi:type="xRayMirrorType" id="27080001" name="Inc. Beam Cu W/Si (hybrid MPD)" hybrid="true">
				<crystal type="Graded" shape="Parabolic">W/Si</crystal>
				<acceptanceAngle unit="deg">0.800</acceptanceAngle>
				<length unit="mm">55.3</length>
			</xRayMirror>
			<monochromator xsi:type="monochromatorType" id="23090002" name="Hybrid monochr. 2xGe220 Cu asym." hybrid="true">
				<crystal type="Asymmetric" shape="Flat">Ge</crystal>
				<numberOfReflections>2</numberOfReflections>
				<hkl>
					<h>2</h>
					<k>2</k>
					<l>0</l>
				</hkl>
			</monochromator>
			<divergenceSlit xsi:type="fixedDivergenceSlitType" id="22010005" name="Fixed slit 1/4°">
				<distanceToSample unit="mm">179.30</distanceToSample>
				<height unit="mm">0.38</height>
			</divergenceSlit>
		</incidentBeamPath>
		<diffractedBeamPath>
			<radius unit="mm">240.00</radius>
			<antiScatterSlit xsi:type="fixedAntiScatterSlitType" id="22060009" name="Programmable anti-scatter slit">
				<angle unit="deg">4</angle>
			</antiScatterSlit>
			<detector xsi:type="areaDetectorType" id="7010020" name="PIXcel3D-Medipix3 1x1 detector">
				<phd unit="%">
					<lowerLevel>25</lowerLevel>
					<upperLevel>70</upperLevel>
				</phd>
				<mode>Scanning snapshot equatorial</mode>
				<activeChannelsEquatorial>255</activeChannelsEquatorial>
				<activeChannelsAxial>255</activeChannelsAxial>
				<pitchEquatorial unit="mm">0.05500</pitchEquatorial>
				<pitchAxial unit="mm">0.05500</pitchAxial>
				<readOutPeriod unit="seconds">0.980</readOutPeriod>
			</detector>
		</diffractedBeamPath>
		<scan status="Completed" appendNumber="0" scanAxis="2Theta" mode="Continuous">
			<header>
				<startTimeStamp>2023-05-17T14:10:36-04:00</startTimeStamp>
				<endTimeStamp>2023-05-17T14:25:41-04:00</endTimeStamp>
				<author>
					<name>User</name>
				</author>
				<source>
					<applicationSoftware version="7.1">Data Collector</applicationSoftware>
					<instrumentControlSoftware version="8.2  20201204">EMPYREAN</instrumentControlSoftware>
					<instrumentID>0000000011260721</instrumentID>
				</source>
			</header>
			<dataPoints>
				<positions axis="2Theta" unit="deg">
					<startPosition>74.0922063943918</startPosition>
					<endPosition>77.4394761656082</endPosition>
				</positions>
				<positions axis="Omega" unit="deg">
					<commonPosition>19.44802064</commonPosition>
				</positions>
				<positions axis="Phi" unit="deg">
					<commonPosition>7.61</commonPosition>
				</positions>
				<positions axis="Chi" unit="deg">
					<commonPosition>0</commonPosition>
				</positions>
				<positions axis="Z" unit="mm">
					<commonPosition>8.488</commonPosition>
				</positions>
				<commonCountingTime unit="seconds">0.974</commonCountingTime>
				<counts unit="counts">0 0 0 1 1 0 0 0 0 1 0 0 0 0 0 0 0 0 0 1 0 0 1 0 0 0 0 0 0 0 0 0 0 1 0 1 0 0 0 0 1 1 0 0 0 0 0 0 1 0 1 0 0 0 0 0 0 0 0 1 0 0 0 0 0 0 1 0 1 0 0 0 1 1 0 0 0 0 0 0 0 0 0 0 2 0 1 0 2 0 0 0 0 0 2 0 0 2 0 0 0 0 2 0 0 0 0 1 1 0 0 0 0 0 0 0 0 0 0 2 0 0 1 1 1 0 0 0 0 1 0 0 0 1 0 1 0 0 0 0 0 0 0 0 0 0 0 0 1 0 1 0 0 1 0 0 0 2 1 1 1 0 1 1 0 0 0 0 0 1 0 0 1 1 1 0 1 0 1 0 0 0 0 1 0 0 0 1 0 0 0 1 0 0 1 0 1 1 0 1 0 0 0 0 0 1 1 0 1 2 0 0 1 0 0 1 0 1 0 0 3 1 2 0 0 0 2 0 1 0 0 1 0 0 1 1 1 0 0 1 1 1 0 0 1 2 0 1 0 0 0 2 0 1 0</counts>
			</dataPoints>
		</scan>
		<scan status="Completed" appendNumber="0" scanAxis="2Theta" mode="Continuous">
			<header>
				<startTimeStamp>2023-05-17T14:10:36-04:00</startTimeStamp>
				<endTimeStamp>2023-05-17T14:25:41-04:00</endTimeStamp>
				<author>
					<name>User</name>
				</author>
				<source>
					<applicationSoftware version="7.1">Data Collector</applicationSoftware>
					<instrumentControlSoftware version="8.2  20201204">EMPYREAN</instrumentControlSoftware>
					<instrumentID>0000000011260721</instrumentID>
				</source>
			</header>
			<dataPoints>
				<positions axis="2Theta" unit="deg">
					<startPosition>74.0954889650716</startPosition>
					<endPosition>77.4427587362881</endPosition>
				</positions>
				<positions axis="Omega" unit="deg">
					<commonPosition>19.4496619253399</commonPosition>
				</positions>
				<positions axis="Phi" unit="deg">
					<commonPosition>7.61</commonPosition>
				</positions>
				<positions axis="Chi" unit="deg">
					<commonPosition>0</commonPosition>
				</positions>
				<positions axis="Z" unit="mm">
					<commonPosition>8.488</commonPosition>
				</positions>
				<commonCountingTime unit="seconds">0.974</commonCountingTime>
				<counts unit="counts">0 0 0 0 0 0 1 1 0 1 0 0 1 1 0 1 0 0 0 0 0 0 0 0 0 0 0 0 0 0 1 0 0 0 1 0 0 0 0 0 0 0 0 0 0 0 0 0 1 0 1 0 0 0 0 1 0 0 0 0 0 1 0 0 0 1 0 0 0 0 1 0 1 0 0 0 1 0 0 0 4 0 0 0 0 0 1 0 0 0 0 1 0 0 0 0 0 0 2 0 0 0 1 0 0 1 0 1 0 0 0 0 0 1 1 0 0 0 0 0 0 1 0 0 0 0 1 0 0 2 1 0 0 0 0 0 1 0 1 0 1 0 0 0 0 0 0 0 2 1 0 0 0 1 0 0 0 0 0 0 0 2 0 0 0 1 0 0 0 0 0 0 1 1 0 0 1 0 0 0 0 2 0 0 0 0 0 0 0 0 0 0 0 0 1 1 0 1 0 1 0 1 0 0 1 2 0 0 1 1 1 0 0 0 0 0 1 1 0 0 0 1 1 0 2 0 0 1 0 0 1 0 0 0 0 0 0 0 0 0 0 2 1 0 0 0 0 0 0 0 0 0 0 1 0</counts>
			</dataPoints>
		</scan>
		<scan status="Completed" appendNumber="0" scanAxis="2Theta" mode="Continuous">
			<header>
				<startTimeStamp>2023-05-17T14:10:36-04:00</startTimeStamp>
				<endTimeStamp>2023-05-17T14:25:41-04:00</endTimeStamp>
				<author>
					<name>User</name>
				</author>
				<source>
					<applicationSoftware version="7.1">Data Collector</applicationSoftware>
					<instrumentControlSoftware version="8.2  20201204">EMPYREAN</instrumentControlSoftware>
					<instrumentID>0000000011260721</instrumentID>
				</source>
			</header>
			<dataPoints>
				<positions axis="2Theta" unit="deg">
					<startPosition>74.0987715357514</startPosition>
					<endPosition>77.4460413069679</endPosition>
				</positions>
				<positions axis="Omega" unit="deg">
					<commonPosition>19.4513032106798</commonPosition>
				</positions>
				<positions axis="Phi" unit="deg">
					<commonPosition>7.61</commonPosition>
				</positions>
				<positions axis="Chi" unit="deg">
					<commonPosition>0</commonPosition>
				</positions>
				<positions axis="Z" unit="mm">
					<commonPosition>8.488</commonPosition>
				</positions>
				<commonCountingTime unit="seconds">0.974</commonCountingTime>
				<counts unit="counts">0 1 1 0 1 0 1 0 0 0 0 0 0 0 0 1 0 0 0 0 0 0 1 0 1 1 0 0 1 1 0 0 0 1 1 0 1 1 0 2 0 0 0 0 3 0 0 0 0 0 0 0 0 0 1 0 0 0 0 0 0 0 0 0 0 0 2 0 0 0 0 0 0 0 0 0 0 0 0 0 1 0 0 0 0 0 0 0 0 0 0 0 0 1 0 0 0 0 0 1 0 0 0 0 0 1 1 0 0 0 0 2 1 0 0 1 1 0 0 0 1 0 0 0 0 0 0 0 0 0 1 0 1 0 0 1 1 2 1 1 0 1 0 0 0 0 0 0 1 0 0 0 0 0 0 0 0 0 0 0 0 0 0 0 1 0 2 0 1 0 0 0 0 0 1 0 1 1 1 0 0 0 0 0 1 0 0 0 1 1 0 0 0 1 0 1 0 0 0 0 0 0 0 0 1 0 0 0 1 2 0 0 3 1 0 2 1 0 2 0 2 0 1 0 0 0 1 0 0 0 0 0 2 0 2 1 0 1 0 0 0 1 1 1 1 0 1 0 0 0 0 0 0 0 0</counts>
			</dataPoints>
		</scan>
		<scan status="Completed" appendNumber="0" scanAxis="2Theta" mode="Continuous">
			<header>
				<startTimeStamp>2023-05-17T14:10:36-04:00</startTimeStamp>
				<endTimeStamp>2023-05-17T14:25:41-04:00</endTimeStamp>
				<author>
					<name>User</name>
				</author>
				<source>
					<applicationSoftware version="7.1">Data Collector</applicationSoftware>
					<instrumentControlSoftware version="8.2  20201204">EMPYREAN</instrumentControlSoftware>
					<instrumentID>0000000011260721</instrumentID>
				</source>
			</header>
			<dataPoints>
				<positions axis="2Theta" unit="deg">
					<startPosition>74.1020541064312</startPosition>
					<endPosition>77.4493238776477</endPosition>
				</positions>
				<positions axis="Omega" unit="deg">
					<commonPosition>19.4529444960197</commonPosition>
				</positions>
				<positions axis="Phi" unit="deg">
					<commonPosition>7.61</commonPosition>
				</positions>
				<positions axis="Chi" unit="deg">
					<commonPosition>0</commonPosition>
				</positions>
				<positions axis="Z" unit="mm">
					<commonPosition>8.488</commonPosition>
				</positions>
				<commonCountingTime unit="seconds">0.974</commonCountingTime>
				<counts unit="counts">0 0 0 0 0 0 0 1 1 1 0 0 0 1 0 0 0 1 0 0 0 0 0 0 1 0 0 0 0 0 0 0 2 0 0 2 0 0 1 0 1 0 0 1 0 0 0 0 1 0 0 0 2 0 0 1 0 0 0 1 0 0 0 1 0 0 0 1 0 1 1 1 1 0 0 1 0 0 0 0 0 0 1 0 1 0 0 0 0 0 0 1 0 0 1 0 0 0 0 0 1 0 1 0 0 0 1 1 0 1 0 0 1 0 0 1 0 1 0 0 1 1 1 1 0 1 1 0 0 0 1 0 0 0 0 0 1 0 0 0 0 0 2 1 0 0 0 0 0 1 1 0 0 1 0 0 0 0 1 0 1 0 2 0 0 0 0 0 0 1 1 0 0 1 0 3 0 0 0 0 0 3 2 0 0 1 0 1 0 0 1 2 0 1 1 0 0 0 2 0 0 0 0 0 0 0 0 1 0 0 0 1 1 1 0 0 0 0 1 1 0 0 0 0 3 0 1 1 0 0 0 1 0 0 1 0 0 0 0 1 1 2 0 0 1 0 0 0 1 0 0 0 0 1 1</counts>
			</dataPoints>
		</scan>
		<scan status="Completed" appendNumber="0" scanAxis="2Theta" mode="Continuous">
			<header>
				<startTimeStamp>2023-05-17T14:10:36-04:00</startTimeStamp>
				<endTimeStamp>2023-05-17T14:25:41-04:00</endTimeStamp>
				<author>
					<name>User</name>
				</author>
				<source>
					<applicationSoftware version="7.1">Data Collector</applicationSoftware>
					<instrumentControlSoftware version="8.2  20201204">EMPYREAN</instrumentControlSoftware>
					<instrumentID>0000000011260721</instrumentID>
				</source>
			</header>
			<dataPoints>
				<positions axis="2Theta" unit="deg">
					<startPosition>74.1053366771111</startPosition>
					<endPosition>77.4526064483275</endPosition>
				</positions>
				<positions axis="Omega" unit="deg">
					<commonPosition>19.4545857813596</commonPosition>
				</positions>
				<positions axis="Phi" unit="deg">
					<commonPosition>7.61</commonPosition>
				</positions>
				<positions axis="Chi" unit="deg">
					<commonPosition>0</commonPosition>
				</positions>
				<positions axis="Z" unit="mm">
					<commonPosition>8.488</commonPosition>
				</positions>
				<commonCountingTime unit="seconds">0.974</commonCountingTime>
				<counts unit="counts">0 1 1 0 1 0 0 1 1 0 0 0 0 1 1 1 0 0 1 1 0 0 0 0 1 0 0 0 1 0 0 0 0 0 0 0 0 0 0 0 0 2 0 0 0 0 0 0 0 2 0 1 0 0 0 1 0 0 0 1 0 0 1 0 0 0 0 1 0 0 0 0 0 0 0 0 0 0 1 0 0 0 0 0 0 1 0 0 0 0 0 0 1 0 0 1 0 0 0 0 0 0 0 0 0 2 1 2 0 0 1 0 0 1 0 1 1 0 1 0 1 0 0 0 0 0 1 0 0 1 0 0 0 1 0 0 1 1 0 0 0 0 0 0 0 1 0 0 0 0 0 0 2 0 1 0 0 0 0 0 0 1 1 0 0 0 0 0 1 0 0 0 1 1 0 0 1 0 0 0 1 0 1 0 0 1 0 0 0 0 0 0 1 0 0 0 0 1 0 0 0 0 1 0 0 1 0 0 1 0 0 0 0 1 0 1 0 0 0 1 0 0 0 4 1 1 1 0 0 0 0 1 0 0 0 0 0 2 1 0 2 0 0 0 0 0 0 0 0 1 1 0 0 0 0</counts>
			</dataPoints>
		</scan>
		<scan status="Completed" appendNumber="0" scanAxis="2Theta" mode="Continuous">
			<header>
				<startTimeStamp>2023-05-17T14:10:36-04:00</startTimeStamp>
				<endTimeStamp>2023-05-17T14:25:41-04:00</endTimeStamp>
				<author>
					<name>User</name>
				</author>
				<source>
					<applicationSoftware version="7.1">Data Collector</applicationSoftware>
					<instrumentControlSoftware version="8.2  20201204">EMPYREAN</instrumentControlSoftware>
					<instrumentID>0000000011260721</instrumentID>
				</source>
			</header>
			<dataPoints>
				<positions axis="2Theta" unit="deg">
					<startPosition>74.1086192477909</startPosition>
					<endPosition>77.4558890190074</endPosition>
				</positions>
				<positions axis="Omega" unit="deg">
					<commonPosition>19.4562270666996</commonPosition>
				</positions>
				<positions axis="Phi" unit="deg">
					<commonPosition>7.61</commonPosition>
				</positions>
				<positions axis="Chi" unit="deg">
					<commonPosition>0</commonPosition>
				</positions>
				<positions axis="Z" unit="mm">
					<commonPosition>8.488</commonPosition>
				</positions>
				<commonCountingTime unit="seconds">0.974</commonCountingTime>
				<counts unit="counts">0 0 2 0 1 0 0 0 0 0 2 0 0 0 0 1 0 0 0 0 1 0 1 0 0 0 0 0 0 0 0 1 0 0 1 0 0 0 2 0 0 0 2 0 1 0 0 1 2 0 0 0 0 0 0 0 0 0 0 0 0 0 1 0 0 1 1 0 0 0 1 0 0 0 0 0 0 2 0 1 0 0 0 0 0 0 0 1 0 0 0 0 0 1 1 0 2 0 1 1 0 0 0 0 0 0 0 1 0 0 0 0 0 0 0 1 0 0 2 1 0 0 0 0 1 0 1 0 0 0 0 0 0 1 2 0 0 0 0 0 0 0 0 0 1 0 0 0 0 0 0 1 0 2 0 0 0 1 0 0 0 0 1 1 3 0 2 0 0 0 1 3 1 0 0 2 0 1 1 0 1 0 0 1 0 0 1 3 0 1 0 2 0 0 2 0 0 1 0 0 0 3 1 1 1 0 1 0 0 0 0 0 0 0 1 1 1 0 1 0 0 0 0 0 0 0 0 0 1 0 0 1 0 1 0 1 2 0 0 0 1 0 0 1 0 2 1 0 0 0 1 0 1 0 0</counts>
			</dataPoints>
		</scan>
		<scan status="Completed" appendNumber="0" scanAxis="2Theta" mode="Continuous">
			<header>
				<startTimeStamp>2023-05-17T14:10:36-04:00</startTimeStamp>
				<endTimeStamp>2023-05-17T14:25:41-04:00</endTimeStamp>
				<author>
					<name>User</name>
				</author>
				<source>
					<applicationSoftware version="7.1">Data Collector</applicationSoftware>
					<instrumentControlSoftware version="8.2  20201204">EMPYREAN</instrumentControlSoftware>
					<instrumentID>0000000011260721</instrumentID>
				</source>
			</header>
			<dataPoints>
				<positions axis="2Theta" unit="deg">
					<startPosition>74.1119018184707</startPosition>
					<endPosition>77.4591715896872</endPosition>
				</positions>
				<positions axis="Omega" unit="deg">
					<commonPosition>19.4578683520395</commonPosition>
				</positions>
				<positions axis="Phi" unit="deg">
					<commonPosition>7.61</commonPosition>
				</positions>
				<positions axis="Chi" unit="deg">
					<commonPosition>0</commonPosition>
				</positions>
				<positions axis="Z" unit="mm">
					<commonPosition>8.488</commonPosition>
				</positions>
				<commonCountingTime unit="seconds">0.974</commonCountingTime>
				<counts unit="counts">1 0 0 1 0 1 0 0 0 0 0 0 0 1 0 1 0 0 0 0 1 0 0 0 2 1 0 0 0 0 2 1 0 0 0 1 0 2 0 0 0 2 0 0 0 0 0 0 1 0 0 0 0 0 0 0 1 1 0 0 0 0 0 0 0 0 0 0 0 0 0 0 0 0 0 1 0 0 0 0 0 0 0 0 1 0 0 1 0 0 1 2 0 0 1 0 0 0 0 0 1 0 0 1 1 0 1 0 0 0 1 0 1 0 0 0 0 0 1 0 1 0 0 1 0 1 1 2 0 0 0 0 0 1 0 1 0 0 0 0 0 0 0 1 0 1 0 0 0 0 0 1 0 1 0 0 0 0 1 2 2 0 0 2 0 0 0 0 0 1 2 0 0 1 0 0 0 0 0 0 1 0 0 0 1 0 0 0 1 0 0 2 0 0 0 0 3 0 0 0 1 0 1 1 1 3 0 0 2 1 1 0 1 0 0 0 0 0 1 0 0 1 0 1 0 0 0 1 0 0 0 0 0 0 0 1 1 3 2 2 1 0 0 0 1 0 1 0 1 0 0 1 0 1 2</counts>
			</dataPoints>
		</scan>
		<scan status="Completed" appendNumber="0" scanAxis="2Theta" mode="Continuous">
			<header>
				<startTimeStamp>2023-05-17T14:10:36-04:00</startTimeStamp>
				<endTimeStamp>2023-05-17T14:25:41-04:00</endTimeStamp>
				<author>
					<name>User</name>
				</author>
				<source>
					<applicationSoftware version="7.1">Data Collector</applicationSoftware>
					<instrumentControlSoftware version="8.2  20201204">EMPYREAN</instrumentControlSoftware>
					<instrumentID>0000000011260721</instrumentID>
				</source>
			</header>
			<dataPoints>
				<positions axis="2Theta" unit="deg">
					<startPosition>74.1151843891505</startPosition>
					<endPosition>77.462454160367</endPosition>
				</positions>
				<positions axis="Omega" unit="deg">
					<commonPosition>19.4595096373794</commonPosition>
				</positions>
				<positions axis="Phi" unit="deg">
					<commonPosition>7.61</commonPosition>
				</positions>
				<positions axis="Chi" unit="deg">
					<commonPosition>0</commonPosition>
				</positions>
				<positions axis="Z" unit="mm">
					<commonPosition>8.488</commonPosition>
				</positions>
				<commonCountingTime unit="seconds">0.974</commonCountingTime>
				<counts unit="counts">1 1 0 0 1 0 0 0 0 0 1 0 0 0 0 0 0 0 0 0 2 1 0 1 0 0 2 0 0 0 0 0 0 0 2 0 0 0 0 0 0 2 0 0 0 0 1 0 0 0 0 0 1 1 1 0 0 0 0 1 1 1 0 1 0 1 0 0 0 0 1 0 2 0 0 1 0 0 0 1 0 0 0 0 0 0 0 0 0 0 1 0 2 0 0 0 0 0 0 0 0 1 0 1 0 1 1 1 2 0 0 0 0 0 0 0 0 1 0 0 0 1 0 1 0 0 1 0 0 1 0 2 0 0 1 0 1 0 1 0 0 0 1 0 0 1 1 1 0 1 0 1 2 1 0 0 1 0 0 0 0 0 1 0 1 0 0 2 2 0 1 0 2 0 2 0 0 1 0 0 1 1 0 1 1 0 0 1 0 1 1 0 1 0 1 0 0 0 0 1 0 0 0 0 0 0 0 0 0 1 1 0 1 1 1 0 0 0 0 0 0 1 0 0 2 0 0 0 0 0 1 0 0 0 1 0 2 0 2 0 2 1 1 0 0 0 2 0 1 0 0 0 0 1 0</counts>
			</dataPoints>
		</scan>
		<scan status="Completed" appendNumber="0" scanAxis="2Theta" mode="Continuous">
			<header>
				<startTimeStamp>2023-05-17T14:10:36-04:00</startTimeStamp>
				<endTimeStamp>2023-05-17T14:25:41-04:00</endTimeStamp>
				<author>
					<name>User</name>
				</author>
				<source>
					<applicationSoftware version="7.1">Data Collector</applicationSoftware>
					<instrumentControlSoftware version="8.2  20201204">EMPYREAN</instrumentControlSoftware>
					<instrumentID>0000000011260721</instrumentID>
				</source>
			</header>
			<dataPoints>
				<positions axis="2Theta" unit="deg">
					<startPosition>74.1184669598304</startPosition>
					<endPosition>77.4657367310468</endPosition>
				</positions>
				<positions axis="Omega" unit="deg">
					<commonPosition>19.4611509227193</commonPosition>
				</positions>
				<positions axis="Phi" unit="deg">
					<commonPosition>7.61</commonPosition>
				</positions>
				<positions axis="Chi" unit="deg">
					<commonPosition>0</commonPosition>
				</positions>
				<positions axis="Z" unit="mm">
					<commonPosition>8.488</commonPosition>
				</positions>
				<commonCountingTime unit="seconds">0.974</commonCountingTime>
				<counts unit="counts">1 0 0 0 2 0 0 0 1 4 0 0 1 1 1 1 0 0 0 0 2 1 1 0 1 0 0 0 0 1 0 0 0 0 1 0 0 0 2 1 0 0 0 2 0 0 0 0 1 1 0 0 0 0 0 0 0 1 3 0 0 0 1 1 0 1 1 0 0 0 0 0 0 0 0 0 0 0 0 0 1 0 0 1 0 0 1 0 1 1 1 0 0 1 0 0 1 0 0 0 0 0 0 0 1 1 0 0 1 0 0 0 0 0 1 0 1 0 0 0 0 0 0 1 0 0 0 0 0 0 0 1 1 0 1 0 1 0 0 1 3 0 0 0 0 0 2 1 0 0 0 0 0 0 0 0 0 0 2 0 0 0 1 2 1 0 0 0 0 0 0 0 1 0 0 0 1 0 1 0 0 1 0 0 2 0 1 1 0 1 0 1 0 2 0 0 3 0 0 0 0 0 1 1 0 0 0 0 0 0 0 0 0 0 0 2 1 1 0 0 0 1 0 1 0 1 0 0 0 1 1 0 0 1 0 0 1 0 0 2 0 0 0 0 0 0 0 0 0 1 0 0 0 2 0</counts>
			</dataPoints>
		</scan>
		<scan status="Completed" appendNumber="0" scanAxis="2Theta" mode="Continuous">
			<header>
				<startTimeStamp>2023-05-17T14:10:36-04:00</startTimeStamp>
				<endTimeStamp>2023-05-17T14:25:41-04:00</endTimeStamp>
				<author>
					<name>User</name>
				</author>
				<source>
					<applicationSoftware version="7.1">Data Collector</applicationSoftware>
					<instrumentControlSoftware version="8.2  20201204">EMPYREAN</instrumentControlSoftware>
					<instrumentID>0000000011260721</instrumentID>
				</source>
			</header>
			<dataPoints>
				<positions axis="2Theta" unit="deg">
					<startPosition>74.1217495305102</startPosition>
					<endPosition>77.4690193017267</endPosition>
				</positions>
				<positions axis="Omega" unit="deg">
					<commonPosition>19.4627922080592</commonPosition>
				</positions>
				<positions axis="Phi" unit="deg">
					<commonPosition>7.61</commonPosition>
				</positions>
				<positions axis="Chi" unit="deg">
					<commonPosition>0</commonPosition>
				</positions>
				<positions axis="Z" unit="mm">
					<commonPosition>8.488</commonPosition>
				</positions>
				<commonCountingTime unit="seconds">0.974</commonCountingTime>
				<counts unit="counts">0 0 1 1 0 0 1 0 0 0 1 2 0 1 0 1 0 0 1 0 0 0 0 0 0 0 0 0 0 0 0 0 3 0 2 0 0 0 0 0 0 0 1 0 0 0 0 0 0 0 0 1 0 0 0 0 0 0 0 0 0 0 0 1 0 0 0 0 0 0 0 0 2 1 2 0 1 2 0 0 0 0 0 0 0 0 0 1 0 1 1 0 2 1 0 1 0 0 2 1 0 0 1 0 0 0 0 1 0 0 0 1 0 0 0 1 0 1 1 0 0 0 0 0 0 0 0 2 0 0 0 1 0 1 1 0 1 1 1 1 1 1 1 1 0 0 0 0 0 0 1 1 1 1 2 1 0 0 0 1 2 2 1 0 0 0 0 0 1 2 0 1 1 0 2 0 1 1 1 0 0 0 1 0 2 1 0 1 0 0 0 0 0 0 0 0 0 1 0 2 2 1 0 0 0 0 0 0 0 0 0 1 0 0 0 0 0 2 1 2 0 0 0 0 1 1 0 0 1 0 0 0 1 1 0 0 0 1 0 0 0 0 1 0 0 0 0 1 0 2 1 0 0 0 0</counts>
			</dataPoints>
		</scan>
		<scan status="Completed" appendNumber="0" scanAxis="2Theta" mode="Continuous">
			<header>
				<startTimeStamp>2023-05-17T14:10:36-04:00</startTimeStamp>
				<endTimeStamp>2023-05-17T14:25:41-04:00</endTimeStamp>
				<author>
					<name>User</name>
				</author>
				<source>
					<applicationSoftware version="7.1">Data Collector</applicationSoftware>
					<instrumentControlSoftware version="8.2  20201204">EMPYREAN</instrumentControlSoftware>
					<instrumentID>0000000011260721</instrumentID>
				</source>
			</header>
			<dataPoints>
				<positions axis="2Theta" unit="deg">
					<startPosition>74.12503210119</startPosition>
					<endPosition>77.4723018724065</endPosition>
				</positions>
				<positions axis="Omega" unit="deg">
					<commonPosition>19.4644334933991</commonPosition>
				</positions>
				<positions axis="Phi" unit="deg">
					<commonPosition>7.61</commonPosition>
				</positions>
				<positions axis="Chi" unit="deg">
					<commonPosition>0</commonPosition>
				</positions>
				<positions axis="Z" unit="mm">
					<commonPosition>8.488</commonPosition>
				</positions>
				<commonCountingTime unit="seconds">0.974</commonCountingTime>
				<counts unit="counts">0 0 0 0 0 0 0 0 0 0 0 0 0 0 0 0 0 0 0 0 0 0 0 0 0 0 0 0 0 1 0 1 1 0 0 0 1 0 0 1 0 0 0 0 0 0 0 0 0 0 0 0 1 0 0 0 0 0 0 1 0 0 0 0 0 0 1 0 0 0 1 0 0 0 0 0 0 0 1 0 0 0 0 0 0 1 1 0 1 1 0 1 0 0 0 1 1 0 0 0 0 0 0 1 0 0 0 0 1 0 0 2 0 0 0 0 0 1 0 0 0 0 0 0 1 0 1 0 2 1 0 0 0 0 0 0 0 0 2 1 0 1 0 1 0 0 2 1 0 0 0 0 0 0 0 0 2 0 0 0 0 0 0 0 0 0 0 0 4 0 1 1 0 0 2 0 0 0 1 0 0 1 0 0 0 1 0 0 1 0 0 0 0 0 1 1 0 1 1 1 1 0 0 1 1 0 0 3 0 0 0 1 0 0 0 0 1 2 0 0 1 1 1 0 0 1 0 0 0 2 0 2 0 1 1 1 1 3 1 1 2 0 2 0 1 0 0 0 0 0 2 1 1 0 1</counts>
			</dataPoints>
		</scan>
		<scan status="Completed" appendNumber="0" scanAxis="2Theta" mode="Continuous">
			<header>
				<startTimeStamp>2023-05-17T14:10:36-04:00</startTimeStamp>
				<endTimeStamp>2023-05-17T14:25:41-04:00</endTimeStamp>
				<author>
					<name>User</name>
				</author>
				<source>
					<applicationSoftware version="7.1">Data Collector</applicationSoftware>
					<instrumentControlSoftware version="8.2  20201204">EMPYREAN</instrumentControlSoftware>
					<instrumentID>0000000011260721</instrumentID>
				</source>
			</header>
			<dataPoints>
				<positions axis="2Theta" unit="deg">
					<startPosition>74.1283146718698</startPosition>
					<endPosition>77.4755844430863</endPosition>
				</positions>
				<positions axis="Omega" unit="deg">
					<commonPosition>19.466074778739</commonPosition>
				</positions>
				<positions axis="Phi" unit="deg">
					<commonPosition>7.61</commonPosition>
				</positions>
				<positions axis="Chi" unit="deg">
					<commonPosition>0</commonPosition>
				</positions>
				<positions axis="Z" unit="mm">
					<commonPosition>8.488</commonPosition>
				</positions>
				<commonCountingTime unit="seconds">0.974</commonCountingTime>
				<counts unit="counts">3 0 0 1 1 0 0 0 1 0 0 0 0 0 0 0 0 0 0 0 1 0 0 0 0 0 0 0 1 1 0 0 0 0 2 0 0 1 0 0 0 1 0 0 0 2 0 1 0 0 1 0 2 0 0 0 0 0 0 0 0 1 1 0 1 1 0 0 0 0 0 0 2 0 0 0 0 0 0 0 0 0 0 0 1 0 0 0 1 0 1 0 0 0 0 1 1 0 0 0 0 0 1 0 0 1 0 1 0 1 1 1 0 1 1 1 1 3 1 1 0 1 0 1 1 1 0 1 0 1 0 0 0 0 0 0 0 0 0 0 0 0 0 0 0 0 0 1 0 0 1 0 1 0 0 1 0 0 0 0 2 0 1 0 1 0 0 3 0 0 0 0 2 0 0 1 0 2 1 0 0 0 0 1 0 0 0 0 0 2 0 0 1 1 0 0 1 0 0 1 0 1 0 2 0 0 1 1 0 0 0 0 1 0 0 0 0 1 0 0 2 0 0 0 2 1 0 1 0 0 1 1 1 1 1 1 1 0 0 0 0 0 0 0 0 0 1 0 0 0 1 0 0 0 0</counts>
			</dataPoints>
		</scan>
		<scan status="Completed" appendNumber="0" scanAxis="2Theta" mode="Continuous">
			<header>
				<startTimeStamp>2023-05-17T14:10:36-04:00</startTimeStamp>
				<endTimeStamp>2023-05-17T14:25:41-04:00</endTimeStamp>
				<author>
					<name>User</name>
				</author>
				<source>
					<applicationSoftware version="7.1">Data Collector</applicationSoftware>
					<instrumentControlSoftware version="8.2  20201204">EMPYREAN</instrumentControlSoftware>
					<instrumentID>0000000011260721</instrumentID>
				</source>
			</header>
			<dataPoints>
				<positions axis="2Theta" unit="deg">
					<startPosition>74.1315972425497</startPosition>
					<endPosition>77.4788670137661</endPosition>
				</positions>
				<positions axis="Omega" unit="deg">
					<commonPosition>19.4677160640789</commonPosition>
				</positions>
				<positions axis="Phi" unit="deg">
					<commonPosition>7.61</commonPosition>
				</positions>
				<positions axis="Chi" unit="deg">
					<commonPosition>0</commonPosition>
				</positions>
				<positions axis="Z" unit="mm">
					<commonPosition>8.488</commonPosition>
				</positions>
				<commonCountingTime unit="seconds">0.974</commonCountingTime>
				<counts unit="counts">0 0 0 1 0 0 0 0 0 1 1 1 0 0 0 1 1 1 0 0 0 0 1 0 0 0 1 0 0 0 0 2 0 0 0 0 0 0 0 1 0 0 1 0 1 0 0 0 0 0 0 1 1 0 0 0 0 0 0 0 1 1 0 0 0 0 0 0 0 0 0 0 2 1 0 0 1 1 1 2 0 0 0 0 1 0 1 1 0 0 0 1 1 0 1 0 0 0 0 0 0 0 0 0 0 0 0 0 0 0 2 0 0 0 0 0 0 0 1 0 0 0 0 0 0 0 0 0 0 0 0 1 0 0 0 1 1 0 0 0 0 0 1 0 0 0 0 0 0 2 0 0 0 0 0 0 0 0 0 0 0 0 1 1 0 0 0 1 0 0 0 0 1 2 0 1 1 0 0 1 0 0 0 0 2 1 1 0 2 0 0 0 0 0 0 0 0 0 1 0 1 0 0 0 1 1 0 1 0 0 1 1 0 1 0 0 0 1 1 0 0 0 1 0 1 0 0 1 0 1 1 0 0 0 1 1 1 1 2 0 2 0 1 0 0 0 0 0 0 0 0 1 0 0 1</counts>
			</dataPoints>
		</scan>
		<scan status="Completed" appendNumber="0" scanAxis="2Theta" mode="Continuous">
			<header>
				<startTimeStamp>2023-05-17T14:10:36-04:00</startTimeStamp>
				<endTimeStamp>2023-05-17T14:25:41-04:00</endTimeStamp>
				<author>
					<name>User</name>
				</author>
				<source>
					<applicationSoftware version="7.1">Data Collector</applicationSoftware>
					<instrumentControlSoftware version="8.2  20201204">EMPYREAN</instrumentControlSoftware>
					<instrumentID>0000000011260721</instrumentID>
				</source>
			</header>
			<dataPoints>
				<positions axis="2Theta" unit="deg">
					<startPosition>74.1348798132295</startPosition>
					<endPosition>77.482149584446</endPosition>
				</positions>
				<positions axis="Omega" unit="deg">
					<commonPosition>19.4693573494189</commonPosition>
				</positions>
				<positions axis="Phi" unit="deg">
					<commonPosition>7.61</commonPosition>
				</positions>
				<positions axis="Chi" unit="deg">
					<commonPosition>0</commonPosition>
				</positions>
				<positions axis="Z" unit="mm">
					<commonPosition>8.488</commonPosition>
				</positions>
				<commonCountingTime unit="seconds">0.974</commonCountingTime>
				<counts unit="counts">0 0 0 1 0 0 0 0 0 0 0 0 0 0 0 0 1 2 0 0 1 0 1 0 1 0 1 0 0 0 0 0 0 0 0 2 0 0 0 1 0 2 0 0 0 0 1 0 0 1 0 0 0 0 0 0 0 0 1 0 0 0 0 0 1 2 0 0 0 0 1 0 0 0 0 0 0 0 1 1 0 0 0 1 0 1 0 0 0 0 0 0 0 0 0 0 0 0 0 0 0 0 0 0 0 1 1 0 0 0 0 0 1 0 0 1 0 0 0 0 0 0 0 0 2 0 0 1 0 2 1 0 1 0 0 0 0 2 1 0 1 0 0 0 0 0 0 0 1 0 0 0 0 1 1 0 0 0 1 0 0 0 1 1 0 1 0 0 0 0 0 0 0 0 1 1 1 1 0 3 0 0 1 1 0 0 1 2 0 0 0 0 2 0 0 0 0 0 0 0 1 2 0 1 0 2 0 0 0 0 0 0 1 0 1 1 0 1 0 1 0 1 0 0 1 3 1 0 0 2 0 0 0 0 1 0 0 0 1 1 0 1 0 1 0 0 1 0 0 0 1 1 0 0 0</counts>
			</dataPoints>
		</scan>
		<scan status="Completed" appendNumber="0" scanAxis="2Theta" mode="Continuous">
			<header>
				<startTimeStamp>2023-05-17T14:10:36-04:00</startTimeStamp>
				<endTimeStamp>2023-05-17T14:25:41-04:00</endTimeStamp>
				<author>
					<name>User</name>
				</author>
				<source>
					<applicationSoftware version="7.1">Data Collector</applicationSoftware>
					<instrumentControlSoftware version="8.2  20201204">EMPYREAN</instrumentControlSoftware>
					<instrumentID>0000000011260721</instrumentID>
				</source>
			</header>
			<dataPoints>
				<positions axis="2Theta" unit="deg">
					<startPosition>74.1381623839093</startPosition>
					<endPosition>77.4854321551258</endPosition>
				</positions>
				<positions axis="Omega" unit="deg">
					<commonPosition>19.4709986347588</commonPosition>
				</positions>
				<positions axis="Phi" unit="deg">
					<commonPosition>7.61</commonPosition>
				</positions>
				<positions axis="Chi" unit="deg">
					<commonPosition>0</commonPosition>
				</positions>
				<positions axis="Z" unit="mm">
					<commonPosition>8.488</commonPosition>
				</positions>
				<commonCountingTime unit="seconds">0.974</commonCountingTime>
				<counts unit="counts">0 0 0 0 0 0 1 0 0 0 1 0 0 0 0 0 1 0 0 0 0 1 0 0 0 0 1 0 0 0 0 0 0 0 0 0 1 0 1 0 0 1 0 2 1 1 0 0 1 0 0 0 0 0 1 0 0 0 0 0 0 0 0 0 0 0 1 1 1 1 3 1 2 0 0 0 0 0 1 1 0 0 1 1 1 0 1 0 1 0 0 2 0 0 0 0 1 0 0 1 1 1 0 0 2 1 0 0 0 2 0 0 0 0 0 0 0 0 2 1 1 0 0 0 1 1 1 0 0 0 0 1 0 0 1 1 0 0 0 1 0 0 0 0 1 0 0 0 1 0 0 0 0 0 0 0 0 1 0 1 0 2 0 0 0 0 0 1 1 1 0 0 0 1 1 0 0 0 1 0 0 0 1 0 0 0 0 1 1 2 0 0 0 0 0 2 0 0 0 0 0 1 0 0 1 0 1 0 0 0 0 0 1 1 2 1 0 0 0 0 1 0 1 0 0 0 0 0 0 0 0 0 0 0 2 0 3 1 0 1 0 1 0 1 0 0 0 0 0 1 2 0 0 0 1</counts>
			</dataPoints>
		</scan>
		<scan status="Completed" appendNumber="0" scanAxis="2Theta" mode="Continuous">
			<header>
				<startTimeStamp>2023-05-17T14:10:36-04:00</startTimeStamp>
				<endTimeStamp>2023-05-17T14:25:41-04:00</endTimeStamp>
				<author>
					<name>User</name>
				</author>
				<source>
					<applicationSoftware version="7.1">Data Collector</applicationSoftware>
					<instrumentControlSoftware version="8.2  20201204">EMPYREAN</instrumentControlSoftware>
					<instrumentID>0000000011260721</instrumentID>
				</source>
			</header>
			<dataPoints>
				<positions axis="2Theta" unit="deg">
					<startPosition>74.1414449545891</startPosition>
					<endPosition>77.4887147258056</endPosition>
				</positions>
				<positions axis="Omega" unit="deg">
					<commonPosition>19.4726399200987</commonPosition>
				</positions>
				<positions axis="Phi" unit="deg">
					<commonPosition>7.61</commonPosition>
				</positions>
				<positions axis="Chi" unit="deg">
					<commonPosition>0</commonPosition>
				</positions>
				<positions axis="Z" unit="mm">
					<commonPosition>8.488</commonPosition>
				</positions>
				<commonCountingTime unit="seconds">0.974</commonCountingTime>
				<counts unit="counts">0 1 0 0 0 0 0 0 0 0 0 2 0 0 1 0 0 0 0 1 0 0 0 0 2 0 0 1 0 0 0 0 1 1 0 0 0 0 0 0 1 0 0 0 1 0 0 0 0 0 1 0 0 0 0 0 0 0 0 0 0 0 1 0 0 0 0 0 2 1 0 0 0 0 0 1 0 0 0 0 1 0 0 0 1 0 0 0 1 0 0 0 1 0 0 0 0 0 0 1 1 2 0 0 1 1 1 0 2 2 0 0 0 0 0 1 0 1 1 1 1 0 0 0 0 0 1 1 0 0 2 0 0 0 0 0 0 1 1 2 1 0 0 1 1 0 0 0 1 1 0 1 0 0 0 0 2 1 1 0 1 0 1 0 1 0 0 0 2 1 0 0 0 1 0 2 0 2 1 0 1 0 1 0 0 0 0 0 0 2 0 1 0 0 0 0 0 1 0 0 0 0 0 2 0 0 2 1 0 2 0 0 1 0 2 1 0 0 1 2 1 0 1 0 0 0 3 3 0 0 1 0 2 0 0 1 1 0 0 2 1 1 1 0 0 0 0 0 0 1 0 0 1 0 0</counts>
			</dataPoints>
		</scan>
		<scan status="Completed" appendNumber="0" scanAxis="2Theta" mode="Continuous">
			<header>
				<startTimeStamp>2023-05-17T14:10:36-04:00</startTimeStamp>
				<endTimeStamp>2023-05-17T14:25:41-04:00</endTimeStamp>
				<author>
					<name>User</name>
				</author>
				<source>
					<applicationSoftware version="7.1">Data Collector</applicationSoftware>
					<instrumentControlSoftware version="8.2  20201204">EMPYREAN</instrumentControlSoftware>
					<instrumentID>0000000011260721</instrumentID>
				</source>
			</header>
			<dataPoints>
				<positions axis="2Theta" unit="deg">
					<startPosition>74.144727525269</startPosition>
					<endPosition>77.4919972964854</endPosition>
				</positions>
				<positions axis="Omega" unit="deg">
					<commonPosition>19.4742812054386</commonPosition>
				</positions>
				<positions axis="Phi" unit="deg">
					<commonPosition>7.61</commonPosition>
				</positions>
				<positions axis="Chi" unit="deg">
					<commonPosition>0</commonPosition>
				</positions>
				<positions axis="Z" unit="mm">
					<commonPosition>8.488</commonPosition>
				</positions>
				<commonCountingTime unit="seconds">0.974</commonCountingTime>
				<counts unit="counts">0 0 0 1 1 0 0 0 0 0 2 0 0 0 0 0 1 0 0 1 0 1 1 1 0 0 0 0 1 1 0 0 0 0 0 0 0 0 0 1 1 0 0 1 0 1 0 0 1 0 0 1 0 1 0 0 0 0 0 0 0 0 0 0 0 0 0 0 1 0 0 2 0 0 1 0 0 0 0 0 0 0 0 1 0 0 0 1 0 1 0 0 2 1 1 0 0 0 2 0 0 0 0 0 0 0 2 0 0 0 0 1 0 0 0 0 0 0 0 0 0 0 0 0 0 0 0 0 0 0 0 1 1 0 0 1 0 1 0 0 0 0 0 0 0 2 0 1 0 0 1 1 1 0 1 2 0 0 0 1 1 0 1 1 0 1 3 0 0 0 0 1 1 1 1 0 0 1 1 0 1 0 0 0 0 0 0 0 0 1 1 0 0 0 2 0 0 0 0 0 0 2 1 0 0 2 0 1 0 1 1 1 0 1 0 2 0 0 0 2 0 0 2 0 1 0 0 3 0 1 1 1 1 0 0 0 1 1 2 0 0 0 0 0 0 1 0 1 1 1 0 0 0 0 1</counts>
			</dataPoints>
		</scan>
		<scan status="Completed" appendNumber="0" scanAxis="2Theta" mode="Continuous">
			<header>
				<startTimeStamp>2023-05-17T14:10:36-04:00</startTimeStamp>
				<endTimeStamp>2023-05-17T14:25:41-04:00</endTimeStamp>
				<author>
					<name>User</name>
				</author>
				<source>
					<applicationSoftware version="7.1">Data Collector</applicationSoftware>
					<instrumentControlSoftware version="8.2  20201204">EMPYREAN</instrumentControlSoftware>
					<instrumentID>0000000011260721</instrumentID>
				</source>
			</header>
			<dataPoints>
				<positions axis="2Theta" unit="deg">
					<startPosition>74.1480100959488</startPosition>
					<endPosition>77.4952798671653</endPosition>
				</positions>
				<positions axis="Omega" unit="deg">
					<commonPosition>19.4759224907785</commonPosition>
				</positions>
				<positions axis="Phi" unit="deg">
					<commonPosition>7.61</commonPosition>
				</positions>
				<positions axis="Chi" unit="deg">
					<commonPosition>0</commonPosition>
				</positions>
				<positions axis="Z" unit="mm">
					<commonPosition>8.488</commonPosition>
				</positions>
				<commonCountingTime unit="seconds">0.974</commonCountingTime>
				<counts unit="counts">0 0 1 0 0 0 0 0 2 0 0 0 1 0 0 1 0 0 0 0 0 1 0 0 0 0 1 0 0 1 0 1 0 1 1 0 0 1 1 0 1 0 2 0 0 1 0 0 0 1 0 1 1 1 0 1 1 0 0 0 1 0 1 1 0 0 0 0 0 1 0 0 0 0 0 0 0 0 0 0 0 0 0 1 0 0 0 0 0 0 0 0 0 0 1 0 0 1 0 0 0 2 0 1 2 2 0 0 0 1 0 0 0 0 1 0 0 1 0 0 0 0 0 0 1 0 0 0 0 0 0 0 1 0 0 0 2 0 2 0 1 1 0 1 0 0 0 0 0 0 0 0 0 0 0 0 1 0 0 0 0 0 1 1 0 0 2 0 1 0 0 1 0 1 0 1 0 0 0 1 1 1 0 0 0 0 1 1 1 0 1 1 1 0 0 0 0 0 0 0 0 0 0 0 0 0 2 0 0 0 3 2 0 1 0 2 0 0 0 0 0 0 0 0 0 1 0 0 1 0 0 0 0 0 1 0 1 0 0 0 1 0 0 0 0 0 0 0 1 0 0 1 0 0 0</counts>
			</dataPoints>
		</scan>
		<scan status="Completed" appendNumber="0" scanAxis="2Theta" mode="Continuous">
			<header>
				<startTimeStamp>2023-05-17T14:10:36-04:00</startTimeStamp>
				<endTimeStamp>2023-05-17T14:25:41-04:00</endTimeStamp>
				<author>
					<name>User</name>
				</author>
				<source>
					<applicationSoftware version="7.1">Data Collector</applicationSoftware>
					<instrumentControlSoftware version="8.2  20201204">EMPYREAN</instrumentControlSoftware>
					<instrumentID>0000000011260721</instrumentID>
				</source>
			</header>
			<dataPoints>
				<positions axis="2Theta" unit="deg">
					<startPosition>74.1512926666286</startPosition>
					<endPosition>77.4985624378451</endPosition>
				</positions>
				<positions axis="Omega" unit="deg">
					<commonPosition>19.4775637761184</commonPosition>
				</positions>
				<positions axis="Phi" unit="deg">
					<commonPosition>7.61</commonPosition>
				</positions>
				<positions axis="Chi" unit="deg">
					<commonPosition>0</commonPosition>
				</positions>
				<positions axis="Z" unit="mm">
					<commonPosition>8.488</commonPosition>
				</positions>
				<commonCountingTime unit="seconds">0.974</commonCountingTime>
				<counts unit="counts">0 1 1 1 0 0 1 0 0 0 1 0 1 0 0 0 1 1 0 0 0 0 0 0 0 0 1 0 0 0 0 1 0 0 0 0 0 0 1 0 0 0 0 1 2 2 2 0 0 0 1 0 0 1 0 1 0 1 0 1 0 1 0 0 0 0 0 2 0 0 0 0 0 2 0 0 0 1 0 2 1 1 1 0 0 0 0 0 1 1 0 0 0 0 1 0 0 0 0 0 1 0 2 0 1 1 1 1 2 0 0 0 1 0 1 0 1 0 1 0 0 0 0 1 1 0 0 0 0 0 0 0 0 0 1 0 0 1 0 1 0 0 0 0 0 0 0 0 0 0 1 0 0 1 0 1 0 0 1 0 0 0 0 1 0 0 0 0 0 1 0 0 0 0 1 0 1 0 0 0 0 0 0 1 0 1 0 0 0 1 0 0 1 0 0 0 0 0 0 1 1 3 2 1 1 0 1 2 0 0 0 0 0 0 1 0 1 1 0 1 0 0 0 0 0 0 0 0 1 2 2 1 1 0 2 0 0 0 0 0 0 0 0 1 0 0 0 3 0 0 1 0 0 1 1</counts>
			</dataPoints>
		</scan>
		<scan status="Completed" appendNumber="0" scanAxis="2Theta" mode="Continuous">
			<header>
				<startTimeStamp>2023-05-17T14:10:36-04:00</startTimeStamp>
				<endTimeStamp>2023-05-17T14:25:41-04:00</endTimeStamp>
				<author>
					<name>User</name>
				</author>
				<source>
					<applicationSoftware version="7.1">Data Collector</applicationSoftware>
					<instrumentControlSoftware version="8.2  20201204">EMPYREAN</instrumentControlSoftware>
					<instrumentID>0000000011260721</instrumentID>
				</source>
			</header>
			<dataPoints>
				<positions axis="2Theta" unit="deg">
					<startPosition>74.1545752373084</startPosition>
					<endPosition>77.5018450085249</endPosition>
				</positions>
				<positions axis="Omega" unit="deg">
					<commonPosition>19.4792050614583</commonPosition>
				</positions>
				<positions axis="Phi" unit="deg">
					<commonPosition>7.61</commonPosition>
				</positions>
				<positions axis="Chi" unit="deg">
					<commonPosition>0</commonPosition>
				</positions>
				<positions axis="Z" unit="mm">
					<commonPosition>8.488</commonPosition>
				</positions>
				<commonCountingTime unit="seconds">0.974</commonCountingTime>
				<counts unit="counts">1 1 0 0 0 0 0 0 0 0 0 1 1 0 0 0 0 0 0 0 0 0 2 0 1 0 0 0 1 1 0 0 1 0 1 1 0 0 1 0 1 0 2 0 1 1 0 1 0 0 0 1 0 0 0 0 0 0 0 1 1 0 0 1 0 0 1 0 0 1 1 1 0 1 0 1 1 0 0 0 0 1 0 0 0 0 0 0 0 0 0 0 1 0 0 0 0 0 1 0 1 1 1 0 0 0 0 0 0 0 0 0 0 0 0 1 0 1 0 0 0 1 1 0 0 0 0 0 0 0 0 0 1 2 0 1 0 1 1 0 1 0 0 2 0 0 0 0 1 0 0 0 1 1 1 1 2 0 1 0 0 0 0 1 0 0 0 1 0 1 0 0 0 0 0 0 3 2 0 0 0 0 0 1 0 0 1 2 0 0 0 0 1 1 2 0 1 0 0 0 1 0 2 0 0 0 1 1 1 0 1 0 0 0 1 1 0 0 1 0 1 0 1 1 1 0 0 3 1 1 0 2 0 1 2 0 0 1 0 3 0 3 1 1 0 0 0 1 0 1 0 2 0 0 1</counts>
			</dataPoints>
		</scan>
		<scan status="Completed" appendNumber="0" scanAxis="2Theta" mode="Continuous">
			<header>
				<startTimeStamp>2023-05-17T14:10:36-04:00</startTimeStamp>
				<endTimeStamp>2023-05-17T14:25:41-04:00</endTimeStamp>
				<author>
					<name>User</name>
				</author>
				<source>
					<applicationSoftware version="7.1">Data Collector</applicationSoftware>
					<instrumentControlSoftware version="8.2  20201204">EMPYREAN</instrumentControlSoftware>
					<instrumentID>0000000011260721</instrumentID>
				</source>
			</header>
			<dataPoints>
				<positions axis="2Theta" unit="deg">
					<startPosition>74.1578578079883</startPosition>
					<endPosition>77.5051275792047</endPosition>
				</positions>
				<positions axis="Omega" unit="deg">
					<commonPosition>19.4808463467982</commonPosition>
				</positions>
				<positions axis="Phi" unit="deg">
					<commonPosition>7.61</commonPosition>
				</positions>
				<positions axis="Chi" unit="deg">
					<commonPosition>0</commonPosition>
				</positions>
				<positions axis="Z" unit="mm">
					<commonPosition>8.488</commonPosition>
				</positions>
				<commonCountingTime unit="seconds">0.974</commonCountingTime>
				<counts unit="counts">0 1 0 0 0 0 1 0 1 0 0 0 0 0 0 1 0 0 0 0 0 1 0 0 0 0 1 1 0 0 0 0 1 2 0 1 0 1 1 0 0 0 0 0 0 0 0 0 0 0 0 0 0 0 0 1 1 0 2 0 1 0 0 0 1 0 0 0 0 0 0 1 0 0 0 0 1 0 0 0 1 0 0 0 0 0 0 0 1 0 0 1 1 0 2 0 0 1 0 2 0 2 1 2 0 0 0 1 1 0 0 0 2 0 0 0 0 1 1 0 0 0 0 0 0 0 0 0 0 0 1 1 0 0 0 0 0 3 0 0 0 0 0 0 1 0 0 0 1 0 2 0 0 1 0 1 0 0 0 3 0 1 2 0 0 1 0 0 1 0 1 1 0 0 1 0 1 0 1 1 2 0 0 0 0 0 1 0 1 1 0 1 0 0 1 0 1 0 1 0 0 0 0 1 0 1 0 0 0 1 1 0 0 0 0 2 0 1 1 0 0 0 0 1 1 0 0 1 0 0 0 0 1 0 1 0 0 1 1 2 1 0 0 1 0 0 1 1 0 0 0 2 1 0 0</counts>
[...]
					<commonPosition>0</commonPosition>
				</positions>
				<positions axis="Z" unit="mm">
					<commonPosition>8.488</commonPosition>
				</positions>
				<commonCountingTime unit="seconds">0.974</commonCountingTime>
				<counts unit="counts">1 0 0 0 0 0 0 0 0 0 2 0 0 0 0 1 0 0 0 0 0 1 1 0 0 0 1 0 2 1 1 0 0 0 1 1 1 1 0 0 0 3 2 1 0 0 1 0 0 0 0 0 0 0 0 0 3 0 0 1 0 1 0 1 2 0 0 1 1 1 0 0 0 0 0 0 0 0 1 0 0 0 1 1 2 0 1 0 0 1 0 1 0 0 0 1 0 1 0 0 0 0 0 1 0 2 1 2 0 0 0 0 0 0 0 0 2 0 1 0 1 0 0 0 1 0 0 0 0 0 1 0 0 1 0 0 0 0 0 1 0 0 0 1 0 0 0 0 0 0 0 0 0 0 0 0 0 0 0 0 1 0 0 0 0 0 0 1 0 0 0 0 0 0 0 0 0 1 0 0 0 0 0 0 0 0 0 0 0 1 1 0 0 1 0 0 0 0 0 0 0 0 0 0 0 1 0 0 0 0 1 0 0 1 0 0 1 0 1 0 0 0 0 0 1 0 1 0 1 0 0 0 0 0 0 0 0 0 0 0 0 2 1 0 0 0 0 0 0 0 1 1 0 0 0</counts>
			</dataPoints>
		</scan>
		<scan status="Completed" appendNumber="0" scanAxis="2Theta" mode="Continuous">
			<header>
				<startTimeStamp>2023-05-17T14:10:36-04:00</startTimeStamp>
				<endTimeStamp>2023-05-17T14:25:41-04:00</endTimeStamp>
				<author>
					<name>User</name>
				</author>
				<source>
					<applicationSoftware version="7.1">Data Collector</applicationSoftware>
					<instrumentControlSoftware version="8.2  20201204">EMPYREAN</instrumentControlSoftware>
					<instrumentID>0000000011260721</instrumentID>
				</source>
			</header>
			<dataPoints>
				<positions axis="2Theta" unit="deg">
					<startPosition>77.0530851475935</startPosition>
					<endPosition>80.40035491881</endPosition>
				</positions>
				<positions axis="Omega" unit="deg">
					<commonPosition>20.9284600166009</commonPosition>
				</positions>
				<positions axis="Phi" unit="deg">
					<commonPosition>7.61</commonPosition>
				</positions>
				<positions axis="Chi" unit="deg">
					<commonPosition>0</commonPosition>
				</positions>
				<positions axis="Z" unit="mm">
					<commonPosition>8.488</commonPosition>
				</positions>
				<commonCountingTime unit="seconds">0.974</commonCountingTime>
				<counts unit="counts">0 1 0 0 0 0 0 0 1 0 0 2 0 3 1 0 1 0 1 2 1 1 3 1 2 0 2 0 0 2 1 0 0 0 0 0 0 0 0 0 1 0 1 0 1 0 1 2 0 0 0 1 2 2 0 0 0 0 2 0 0 1 1 1 0 0 0 0 1 0 1 0 1 1 0 0 1 0 0 0 1 1 1 1 0 1 0 0 1 0 1 0 1 0 0 0 1 1 0 0 1 0 0 0 0 0 0 0 0 1 0 0 1 0 1 0 0 0 0 0 0 0 1 3 1 1 0 1 0 0 0 0 0 0 0 1 0 0 0 1 0 0 0 1 0 0 0 0 0 0 0 0 2 0 0 1 1 0 0 0 1 0 0 0 0 0 0 1 0 0 0 0 0 1 0 0 0 0 0 0 2 0 1 2 0 1 0 0 0 0 0 0 1 0 1 1 0 0 1 0 0 1 0 0 1 0 0 1 0 0 0 0 0 0 0 0 0 0 0 0 0 0 2 0 0 1 0 0 1 0 1 0 1 0 1 1 0 0 0 0 0 0 0 0 1 0 0 0 0 0 1 0 2 1 1</counts>
			</dataPoints>
		</scan>
		<scan status="Completed" appendNumber="0" scanAxis="2Theta" mode="Continuous">
			<header>
				<startTimeStamp>2023-05-17T14:10:36-04:00</startTimeStamp>
				<endTimeStamp>2023-05-17T14:25:41-04:00</endTimeStamp>
				<author>
					<name>User</name>
				</author>
				<source>
					<applicationSoftware version="7.1">Data Collector</applicationSoftware>
					<instrumentControlSoftware version="8.2  20201204">EMPYREAN</instrumentControlSoftware>
					<instrumentID>0000000011260721</instrumentID>
				</source>
			</header>
			<dataPoints>
				<positions axis="2Theta" unit="deg">
					<startPosition>77.0563677182734</startPosition>
					<endPosition>80.4036374894898</endPosition>
				</positions>
				<positions axis="Omega" unit="deg">
					<commonPosition>20.9301013019408</commonPosition>
				</positions>
				<positions axis="Phi" unit="deg">
					<commonPosition>7.61</commonPosition>
				</positions>
				<positions axis="Chi" unit="deg">
					<commonPosition>0</commonPosition>
				</positions>
				<positions axis="Z" unit="mm">
					<commonPosition>8.488</commonPosition>
				</positions>
				<commonCountingTime unit="seconds">0.974</commonCountingTime>
				<counts unit="counts">1 0 0 1 1 1 0 2 0 0 1 1 0 3 1 2 1 0 2 2 0 0 1 0 0 0 1 1 1 1 0 1 2 0 2 0 1 0 0 1 1 1 0 1 1 0 1 0 1 0 1 1 1 1 0 0 0 0 2 0 0 0 0 1 0 0 0 0 0 0 0 0 1 0 0 1 0 1 0 2 0 0 0 0 1 0 1 3 0 1 1 0 0 1 0 0 0 0 0 0 0 0 1 0 0 0 0 0 0 1 0 0 0 0 0 0 0 0 0 0 0 0 0 0 0 0 1 1 0 0 1 1 0 0 0 0 0 0 0 0 0 0 0 0 0 0 0 0 0 0 0 0 2 0 1 1 2 1 0 1 1 0 0 0 0 1 0 0 1 0 0 0 1 0 0 0 0 1 0 0 0 0 0 1 0 1 1 0 1 0 0 0 1 0 0 0 0 0 0 0 1 0 1 0 0 1 1 1 0 0 0 1 0 0 0 1 0 0 0 0 0 0 0 0 1 0 0 1 0 0 0 0 0 0 0 0 0 0 0 0 0 0 0 0 1 0 0 0 1 0 0 0 0 0 0</counts>
			</dataPoints>
		</scan>
		<scan status="Completed" appendNumber="0" scanAxis="2Theta" mode="Continuous">
			<header>
				<startTimeStamp>2023-05-17T14:10:36-04:00</startTimeStamp>
				<endTimeStamp>2023-05-17T14:25:41-04:00</endTimeStamp>
				<author>
					<name>User</name>
				</author>
				<source>
					<applicationSoftware version="7.1">Data Collector</applicationSoftware>
					<instrumentControlSoftware version="8.2  20201204">EMPYREAN</instrumentControlSoftware>
					<instrumentID>0000000011260721</instrumentID>
				</source>
			</header>
			<dataPoints>
				<positions axis="2Theta" unit="deg">
					<startPosition>77.0596502889532</startPosition>
					<endPosition>80.4069200601697</endPosition>
				</positions>
				<positions axis="Omega" unit="deg">
					<commonPosition>20.9317425872807</commonPosition>
				</positions>
				<positions axis="Phi" unit="deg">
					<commonPosition>7.61</commonPosition>
				</positions>
				<positions axis="Chi" unit="deg">
					<commonPosition>0</commonPosition>
				</positions>
				<positions axis="Z" unit="mm">
					<commonPosition>8.488</commonPosition>
				</positions>
				<commonCountingTime unit="seconds">0.974</commonCountingTime>
				<counts unit="counts">0 1 2 0 0 0 0 0 1 1 1 1 1 0 1 2 0 0 0 0 1 1 2 2 0 2 0 0 0 0 1 1 0 0 0 1 1 0 1 0 1 1 0 0 2 0 0 0 1 2 0 0 3 1 0 1 1 1 0 1 0 0 0 0 0 0 0 0 0 0 0 0 1 1 0 0 0 0 0 0 1 0 0 1 1 0 0 1 1 1 0 0 0 0 0 0 1 1 0 1 0 0 1 0 0 0 1 1 0 0 0 0 0 0 1 0 0 0 0 0 0 0 0 0 0 1 2 0 0 0 1 0 0 0 0 0 0 1 2 2 1 1 0 0 0 1 1 0 0 1 0 0 0 1 0 0 0 1 0 1 0 0 1 0 1 3 0 0 0 0 0 0 0 1 1 0 0 0 0 0 1 0 0 0 0 0 0 0 0 0 1 0 0 0 1 0 0 0 1 0 0 0 2 0 1 0 1 0 0 0 1 0 1 0 0 2 0 0 0 0 0 0 0 0 0 0 0 0 0 0 1 0 1 1 0 0 0 2 0 0 0 0 2 0 0 0 0 0 0 1 0 0 0 0 0</counts>
			</dataPoints>
		</scan>
		<scan status="Completed" appendNumber="0" scanAxis="2Theta" mode="Continuous">
			<header>
				<startTimeStamp>2023-05-17T14:10:36-04:00</startTimeStamp>
				<endTimeStamp>2023-05-17T14:25:41-04:00</endTimeStamp>
				<author>
					<name>User</name>
				</author>
				<source>
					<applicationSoftware version="7.1">Data Collector</applicationSoftware>
					<instrumentControlSoftware version="8.2  20201204">EMPYREAN</instrumentControlSoftware>
					<instrumentID>0000000011260721</instrumentID>
				</source>
			</header>
			<dataPoints>
				<positions axis="2Theta" unit="deg">
					<startPosition>77.062932859633</startPosition>
					<endPosition>80.4102026308495</endPosition>
				</positions>
				<positions axis="Omega" unit="deg">
					<commonPosition>20.9333838726206</commonPosition>
				</positions>
				<positions axis="Phi" unit="deg">
					<commonPosition>7.61</commonPosition>
				</positions>
				<positions axis="Chi" unit="deg">
					<commonPosition>0</commonPosition>
				</positions>
				<positions axis="Z" unit="mm">
					<commonPosition>8.488</commonPosition>
				</positions>
				<commonCountingTime unit="seconds">0.974</commonCountingTime>
				<counts unit="counts">0 1 1 0 1 1 0 2 0 0 0 0 0 1 0 0 0 0 0 0 1 2 2 0 1 0 0 1 0 0 1 0 0 1 0 0 0 1 0 0 1 0 1 0 0 0 2 2 0 4 0 0 0 1 0 0 0 0 1 0 0 2 0 0 0 0 1 0 1 0 0 0 0 0 0 1 0 1 1 1 0 1 0 1 0 1 0 0 0 0 0 1 0 0 1 2 0 0 0 0 0 0 0 0 0 1 0 1 1 1 1 0 1 0 0 0 0 0 0 0 0 1 0 0 0 0 1 2 0 0 1 0 0 0 0 0 0 0 1 0 0 0 1 0 1 0 0 0 0 0 1 1 0 0 0 0 0 0 0 1 0 1 0 0 0 1 0 0 0 0 0 0 1 0 0 0 1 0 0 1 0 0 0 1 1 0 0 0 1 0 0 0 0 0 0 0 0 2 1 0 0 0 2 0 0 0 1 1 0 0 0 0 0 1 0 0 1 1 0 0 0 0 0 0 1 1 0 0 0 1 1 0 1 0 1 0 0 0 0 0 0 0 0 0 0 1 0 0 0 0 0 1 2 1 0</counts>
			</dataPoints>
		</scan>
		<scan status="Completed" appendNumber="0" scanAxis="2Theta" mode="Continuous">
			<header>
				<startTimeStamp>2023-05-17T14:10:36-04:00</startTimeStamp>
				<endTimeStamp>2023-05-17T14:25:41-04:00</endTimeStamp>
				<author>
					<name>User</name>
				</author>
				<source>
					<applicationSoftware version="7.1">Data Collector</applicationSoftware>
					<instrumentControlSoftware version="8.2  20201204">EMPYREAN</instrumentControlSoftware>
					<instrumentID>0000000011260721</instrumentID>
				</source>
			</header>
			<dataPoints>
				<positions axis="2Theta" unit="deg">
					<startPosition>77.0662154303128</startPosition>
					<endPosition>80.4134852015293</endPosition>
				</positions>
				<positions axis="Omega" unit="deg">
					<commonPosition>20.9350251579605</commonPosition>
				</positions>
				<positions axis="Phi" unit="deg">
					<commonPosition>7.61</commonPosition>
				</positions>
				<positions axis="Chi" unit="deg">
					<commonPosition>0</commonPosition>
				</positions>
				<positions axis="Z" unit="mm">
					<commonPosition>8.488</commonPosition>
				</positions>
				<commonCountingTime unit="seconds">0.974</commonCountingTime>
				<counts unit="counts">2 0 1 0 0 0 0 0 1 0 0 0 1 1 0 0 1 0 1 1 2 0 0 0 0 1 1 1 2 0 0 0 1 0 0 0 0 0 2 0 0 0 1 1 1 0 0 2 1 1 2 0 2 0 0 0 0 2 0 1 0 1 0 1 1 0 0 0 0 1 0 0 0 1 1 0 2 0 0 0 1 1 0 0 1 1 0 2 0 0 0 1 0 0 1 0 0 0 1 0 1 0 0 1 1 0 0 0 1 0 0 0 1 1 0 0 0 1 2 0 0 0 0 1 0 0 0 0 0 0 0 0 0 1 0 2 1 0 0 0 0 0 0 0 0 0 1 1 1 0 1 0 0 0 0 1 0 0 0 1 0 0 1 0 0 0 0 0 0 0 0 0 0 0 0 1 1 0 3 1 0 0 1 0 0 0 1 0 0 1 0 2 0 3 0 0 0 0 0 0 0 0 1 0 0 0 0 0 0 0 0 0 0 0 0 0 0 0 1 0 0 0 0 0 1 0 0 0 0 0 1 1 1 0 1 0 0 0 0 0 0 0 0 1 1 0 0 0 0 0 0 0 1 0 0</counts>
			</dataPoints>
		</scan>
		<scan status="Completed" appendNumber="0" scanAxis="2Theta" mode="Continuous">
			<header>
				<startTimeStamp>2023-05-17T14:10:36-04:00</startTimeStamp>
				<endTimeStamp>2023-05-17T14:25:41-04:00</endTimeStamp>
				<author>
					<name>User</name>
				</author>
				<source>
					<applicationSoftware version="7.1">Data Collector</applicationSoftware>
					<instrumentControlSoftware version="8.2  20201204">EMPYREAN</instrumentControlSoftware>
					<instrumentID>0000000011260721</instrumentID>
				</source>
			</header>
			<dataPoints>
				<positions axis="2Theta" unit="deg">
					<startPosition>77.0694980009926</startPosition>
					<endPosition>80.4167677722091</endPosition>
				</positions>
				<positions axis="Omega" unit="deg">
					<commonPosition>20.9366664433004</commonPosition>
				</positions>
				<positions axis="Phi" unit="deg">
					<commonPosition>7.61</commonPosition>
				</positions>
				<positions axis="Chi" unit="deg">
					<commonPosition>0</commonPosition>
				</positions>
				<positions axis="Z" unit="mm">
					<commonPosition>8.488</commonPosition>
				</positions>
				<commonCountingTime unit="seconds">0.974</commonCountingTime>
				<counts unit="counts">1 0 0 0 0 1 0 2 2 2 1 0 1 0 2 0 1 1 3 1 0 0 0 0 0 0 0 1 1 0 0 1 2 0 0 0 1 1 1 0 0 0 1 0 0 0 0 0 0 0 2 1 0 0 2 0 0 0 1 0 0 0 0 1 3 0 1 0 0 1 2 0 0 0 0 1 2 0 1 1 0 0 0 0 0 0 0 0 0 1 0 1 1 0 1 1 0 0 0 1 0 1 0 0 0 0 2 0 0 0 1 0 0 0 0 0 1 0 0 0 0 0 0 0 0 0 0 1 0 0 0 1 0 0 0 0 0 1 0 1 1 2 0 0 0 0 2 0 1 0 0 0 0 0 0 0 0 0 0 0 0 0 0 0 0 1 0 1 0 1 0 0 0 0 0 0 1 0 0 1 0 1 0 0 0 1 1 1 0 0 0 1 0 1 0 0 0 0 0 0 0 0 0 0 0 0 0 0 0 0 0 0 0 1 0 0 1 0 1 0 0 1 0 0 0 1 0 0 0 0 0 0 0 0 1 1 0 0 0 1 1 0 0 0 1 0 0 0 0 1 0 0 0 0 0</counts>
			</dataPoints>
		</scan>
		<scan status="Completed" appendNumber="0" scanAxis="2Theta" mode="Continuous">
			<header>
				<startTimeStamp>2023-05-17T14:10:36-04:00</startTimeStamp>
				<endTimeStamp>2023-05-17T14:25:41-04:00</endTimeStamp>
				<author>
					<name>User</name>
				</author>
				<source>
					<applicationSoftware version="7.1">Data Collector</applicationSoftware>
					<instrumentControlSoftware version="8.2  20201204">EMPYREAN</instrumentControlSoftware>
					<instrumentID>0000000011260721</instrumentID>
				</source>
			</header>
			<dataPoints>
				<positions axis="2Theta" unit="deg">
					<startPosition>77.0727805716725</startPosition>
					<endPosition>80.4200503428889</endPosition>
				</positions>
				<positions axis="Omega" unit="deg">
					<commonPosition>20.9383077286404</commonPosition>
				</positions>
				<positions axis="Phi" unit="deg">
					<commonPosition>7.61</commonPosition>
				</positions>
				<positions axis="Chi" unit="deg">
					<commonPosition>0</commonPosition>
				</positions>
				<positions axis="Z" unit="mm">
					<commonPosition>8.488</commonPosition>
				</positions>
				<commonCountingTime unit="seconds">0.974</commonCountingTime>
				<counts unit="counts">1 1 0 1 0 1 2 0 0 0 1 1 1 0 0 1 1 0 3 1 0 2 1 0 0 0 0 1 0 1 0 0 1 0 1 0 0 0 0 3 0 0 0 0 1 0 0 0 0 0 0 1 1 1 1 0 0 1 0 0 0 0 0 1 0 0 1 1 1 1 0 0 0 2 1 1 0 1 0 1 0 2 0 1 0 1 0 0 2 0 1 1 1 0 1 1 0 0 0 0 2 0 0 1 1 0 1 0 0 0 1 0 0 0 0 0 0 0 0 1 0 0 0 0 0 0 0 0 0 0 0 1 0 1 0 0 0 1 0 1 0 0 1 0 0 0 0 0 0 0 0 2 0 0 0 1 0 0 0 0 1 0 0 0 0 0 1 0 0 1 0 0 2 0 1 0 1 0 0 0 0 0 1 0 1 1 0 0 0 0 0 0 0 0 0 0 0 0 0 2 0 0 0 0 0 0 0 1 0 0 1 0 0 0 0 0 0 0 0 0 0 0 0 0 0 0 0 1 1 0 0 0 0 0 1 0 0 0 0 0 0 0 0 0 0 0 0 0 1 0 0 0 0 2 0</counts>
			</dataPoints>
		</scan>
		<scan status="Completed" appendNumber="0" scanAxis="2Theta" mode="Continuous">
			<header>
				<startTimeStamp>2023-05-17T14:10:36-04:00</startTimeStamp>
				<endTimeStamp>2023-05-17T14:25:41-04:00</endTimeStamp>
				<author>
					<name>User</name>
				</author>
				<source>
					<applicationSoftware version="7.1">Data Collector</applicationSoftware>
					<instrumentControlSoftware version="8.2  20201204">EMPYREAN</instrumentControlSoftware>
					<instrumentID>0000000011260721</instrumentID>
				</source>
			</header>
			<dataPoints>
				<positions axis="2Theta" unit="deg">
					<startPosition>77.0760631423523</startPosition>
					<endPosition>80.4233329135688</endPosition>
				</positions>
				<positions axis="Omega" unit="deg">
					<commonPosition>20.9399490139803</commonPosition>
				</positions>
				<positions axis="Phi" unit="deg">
					<commonPosition>7.61</commonPosition>
				</positions>
				<positions axis="Chi" unit="deg">
					<commonPosition>0</commonPosition>
				</positions>
				<positions axis="Z" unit="mm">
					<commonPosition>8.488</commonPosition>
				</positions>
				<commonCountingTime unit="seconds">0.974</commonCountingTime>
				<counts unit="counts">1 1 0 1 0 0 0 1 2 0 1 1 0 0 1 0 0 0 1 3 2 1 0 0 0 1 0 0 1 0 1 1 0 1 0 1 0 0 0 0 1 0 0 1 0 0 0 1 0 0 0 0 0 1 1 0 0 1 0 0 1 1 0 0 1 0 0 0 0 0 0 0 1 0 0 0 2 1 1 0 0 0 0 1 1 2 0 0 0 0 0 1 0 0 0 0 0 0 0 1 0 0 1 0 0 1 1 1 1 0 0 0 1 0 0 0 0 0 1 0 0 0 0 0 0 0 0 0 1 0 0 2 0 0 0 2 0 1 0 0 0 0 0 0 1 0 0 1 0 0 0 0 0 0 1 0 0 0 0 0 1 0 0 0 0 0 0 0 0 0 0 0 0 1 1 0 0 0 0 0 2 0 1 0 1 0 0 0 0 0 0 0 0 1 0 0 0 1 0 0 1 0 0 2 0 0 0 0 1 1 0 0 0 1 1 0 0 1 1 0 0 0 0 1 0 0 0 0 0 0 0 0 0 0 0 0 2 0 1 0 0 0 0 1 1 0 0 0 0 0 1 0 0 0 2</counts>
			</dataPoints>
		</scan>
		<scan status="Completed" appendNumber="0" scanAxis="2Theta" mode="Continuous">
			<header>
				<startTimeStamp>2023-05-17T14:10:36-04:00</startTimeStamp>
				<endTimeStamp>2023-05-17T14:25:41-04:00</endTimeStamp>
				<author>
					<name>User</name>
				</author>
				<source>
					<applicationSoftware version="7.1">Data Collector</applicationSoftware>
					<instrumentControlSoftware version="8.2  20201204">EMPYREAN</instrumentControlSoftware>
					<instrumentID>0000000011260721</instrumentID>
				</source>
			</header>
			<dataPoints>
				<positions axis="2Theta" unit="deg">
					<startPosition>77.0793457130321</startPosition>
					<endPosition>80.4266154842486</endPosition>
				</positions>
				<positions axis="Omega" unit="deg">
					<commonPosition>20.9415902993202</commonPosition>
				</positions>
				<positions axis="Phi" unit="deg">
					<commonPosition>7.61</commonPosition>
				</positions>
				<positions axis="Chi" unit="deg">
					<commonPosition>0</commonPosition>
				</positions>
				<positions axis="Z" unit="mm">
					<commonPosition>8.488</commonPosition>
				</positions>
				<commonCountingTime unit="seconds">0.974</commonCountingTime>
				<counts unit="counts">0 0 1 0 0 0 0 0 0 2 0 0 2 0 0 1 2 2 2 0 0 1 0 1 2 0 0 1 0 2 1 0 0 0 0 0 0 1 1 0 0 0 0 0 0 0 0 1 1 0 1 0 0 0 0 2 1 0 0 1 0 0 0 0 0 0 0 0 0 0 0 0 0 0 0 0 0 0 0 0 0 1 0 0 0 0 1 0 1 0 0 0 0 0 1 1 0 0 1 1 1 0 0 0 0 0 0 0 1 2 0 0 0 1 0 0 0 0 1 0 0 0 2 0 0 0 0 0 0 0 0 0 0 0 0 1 0 0 0 0 0 0 0 0 1 1 0 1 1 1 2 0 0 0 0 0 0 0 2 0 0 0 1 0 0 0 0 0 0 0 0 0 1 0 0 1 1 0 0 0 0 0 0 0 0 0 2 2 0 0 0 1 0 0 1 0 0 1 0 1 0 0 0 0 0 1 0 0 0 2 0 0 0 1 1 1 0 0 0 3 0 0 0 0 0 0 0 0 0 0 0 0 0 0 1 0 2 0 0 0 0 0 1 1 0 0 1 2 0 0 1 0 0 0 0</counts>
			</dataPoints>
		</scan>
		<scan status="Completed" appendNumber="0" scanAxis="2Theta" mode="Continuous">
			<header>
				<startTimeStamp>2023-05-17T14:10:36-04:00</startTimeStamp>
				<endTimeStamp>2023-05-17T14:25:41-04:00</endTimeStamp>
				<author>
					<name>User</name>
				</author>
				<source>
					<applicationSoftware version="7.1">Data Collector</applicationSoftware>
					<instrumentControlSoftware version="8.2  20201204">EMPYREAN</instrumentControlSoftware>
					<instrumentID>0000000011260721</instrumentID>
				</source>
			</header>
			<dataPoints>
				<positions axis="2Theta" unit="deg">
					<startPosition>77.082628283712</startPosition>
					<endPosition>80.4298980549284</endPosition>
				</positions>
				<positions axis="Omega" unit="deg">
					<commonPosition>20.9432315846601</commonPosition>
				</positions>
				<positions axis="Phi" unit="deg">
					<commonPosition>7.61</commonPosition>
				</positions>
				<positions axis="Chi" unit="deg">
					<commonPosition>0</commonPosition>
				</positions>
				<positions axis="Z" unit="mm">
					<commonPosition>8.488</commonPosition>
				</positions>
				<commonCountingTime unit="seconds">0.974</commonCountingTime>
				<counts unit="counts">1 1 0 0 1 0 0 0 0 0 3 0 0 1 0 0 0 0 2 0 0 0 1 0 0 0 0 2 1 1 0 0 0 0 0 1 0 0 1 0 0 0 1 0 0 0 0 1 0 0 0 0 1 0 0 0 0 0 0 1 0 1 0 0 0 0 0 0 1 0 0 1 0 0 0 0 1 1 0 2 0 1 0 0 0 0 1 0 0 0 1 0 0 0 0 0 2 0 1 0 0 0 0 0 0 0 0 0 1 1 0 0 0 0 0 0 1 0 0 0 0 1 0 0 0 0 0 0 0 1 0 0 0 0 0 0 0 0 0 1 0 0 0 0 1 0 1 0 0 0 1 0 0 1 0 0 0 0 0 0 0 1 1 0 0 0 0 0 1 0 1 1 0 1 0 0 0 1 0 1 0 0 0 0 0 0 0 1 1 0 0 0 1 0 0 0 0 0 0 0 0 0 1 1 1 0 0 0 0 1 0 0 1 0 0 0 0 1 0 0 0 0 0 0 1 0 1 0 0 0 0 1 1 0 0 0 1 0 0 1 1 0 0 1 0 0 0 0 0 0 0 0 0 0 1</counts>
			</dataPoints>
		</scan>
		<scan status="Completed" appendNumber="0" scanAxis="2Theta" mode="Continuous">
			<header>
				<startTimeStamp>2023-05-17T14:10:36-04:00</startTimeStamp>
				<endTimeStamp>2023-05-17T14:25:41-04:00</endTimeStamp>
				<author>
					<name>User</name>
				</author>
				<source>
					<applicationSoftware version="7.1">Data Collector</applicationSoftware>
					<instrumentControlSoftware version="8.2  20201204">EMPYREAN</instrumentControlSoftware>
					<instrumentID>0000000011260721</instrumentID>
				</source>
			</header>
			<dataPoints>
				<positions axis="2Theta" unit="deg">
					<startPosition>77.0859108543918</startPosition>
					<endPosition>80.4331806256082</endPosition>
				</positions>
				<positions axis="Omega" unit="deg">
					<commonPosition>20.94487287</commonPosition>
				</positions>
				<positions axis="Phi" unit="deg">
					<commonPosition>7.61</commonPosition>
				</positions>
				<positions axis="Chi" unit="deg">
					<commonPosition>0</commonPosition>
				</positions>
				<positions axis="Z" unit="mm">
					<commonPosition>8.488</commonPosition>
				</positions>
				<commonCountingTime unit="seconds">0.974</commonCountingTime>
				<counts unit="counts">0 0 0 0 2 0 0 3 0 1 0 0 0 1 1 0 3 0 0 2 0 0 0 1 0 1 0 0 0 0 0 0 1 1 0 0 0 0 1 0 0 0 1 0 2 1 0 0 2 0 0 0 1 1 2 0 0 1 0 1 0 1 0 3 1 0 0 0 0 0 0 0 0 0 0 0 0 1 0 0 1 1 1 0 1 0 0 0 0 0 1 1 1 1 1 1 1 0 0 0 0 0 0 0 0 0 1 0 0 1 0 1 0 0 0 0 0 0 0 0 0 0 0 2 0 1 0 0 0 0 1 1 0 0 0 1 0 0 0 0 0 0 1 0 0 0 2 1 0 0 1 1 0 0 0 0 0 0 0 1 0 0 0 0 0 0 1 1 0 1 0 0 0 1 0 0 0 0 2 0 0 0 0 0 0 0 0 1 1 0 0 1 1 0 0 0 2 0 0 0 0 1 1 0 1 1 0 0 0 1 0 1 0 1 0 0 0 0 0 0 0 0 1 1 0 0 0 0 0 0 0 0 0 0 0 0 0 0 0 0 1 0 0 0 0 0 0 0 1 0 0 0 0 0 0</counts>
			</dataPoints>
		</scan>
	</xrdMeasurement>
</xrdMeasurements>